<?xml version="1.0"?>
<robot name="pulley_system">
  
  <!-- Base Link -->
  <link name="base_link">
    <visual>
      <geometry>
        <box size="0.2 0.2 0.1"/>
      </geometry>
      <material name="gray">
        <color rgba="0.5 0.5 0.5 1"/>
      </material>
    </visual>
    <collision>
      <geometry>
        <box size="0.2 0.2 0.1"/>
      </geometry>
    </collision>
    <inertial>
      <mass value="1.0"/>
      <inertia ixx="0.01" ixy="0.0" ixz="0.0" iyy="0.01" iyz="0.0" izz="0.01"/>
    </inertial>
  </link>

  <!-- Pulley Link -->
  <link name="pulley">
    <visual>
      <geometry>
        <cylinder radius="0.1" length="0.05"/>
      </geometry>
      <material name="blue">
        <color rgba="0.2 0.2 0.8 1"/>
      </material>
    </visual>
    <collision>
      <geometry>
        <cylinder radius="0.1" length="0.05"/>
      </geometry>
    </collision>
    <inertial>
      <mass value="0.5"/>
      <inertia ixx="0.001" ixy="0.0" ixz="0.0" iyy="0.001" iyz="0.0" izz="0.002"/>
    </inertial>
  </link>

  <!-- Motor Joint (Continuous for unlimited rotation) -->
  <joint name="motor_joint" type="continuous">
    <parent link="base_link"/>
    <child link="pulley"/>
    <origin xyz="0 0 0.1" rpy="0 0 0"/>
    <axis xyz="0 0 1"/>
    <limit effort="10.0" velocity="10.0"/>
    <dynamics damping="0.1" friction="0.1"/>
  </joint>

  <!-- Rope Attachment Point -->
  <link name="rope_attachment">
    <visual>
      <geometry>
        <sphere radius="0.01"/>
      </geometry>
      <material name="red">
        <color rgba="0.8 0.2 0.2 1"/>
      </material>
    </visual>
    <inertial>
      <mass value="0.01"/>
      <inertia ixx="0.0001" ixy="0.0" ixz="0.0" iyy="0.0001" iyz="0.0" izz="0.0001"/>
    </inertial>
  </link>

  <joint name="rope_joint" type="fixed">
    <parent link="pulley"/>
    <child link="rope_attachment"/>
    <origin xyz="0.1 0 0" rpy="0 0 0"/>
  </joint>

  <!-- Gazebo-specific configurations -->
  <gazebo reference="base_link">
    <material>Gazebo/Grey</material>
  </gazebo>

  <gazebo reference="pulley">
    <material>Gazebo/Blue</material>
  </gazebo>

  <gazebo reference="rope_attachment">
    <material>Gazebo/Red</material>
  </gazebo>

  <!-- ROS 2 Control Plugin -->
  <ros2_control name="GazeboSystem" type="system">
    <hardware>
      <plugin>gazebo_ros2_control/GazeboSystem</plugin>
    </hardware>
    <joint name="motor_joint">
      <command_interface name="velocity">
        <param name="min">-10</param>
        <param name="max">10</param>
      </command_interface>
      <state_interface name="position"/>
      <state_interface name="velocity"/>
      <state_interface name="effort"/>
    </joint>
  </ros2_control>

  <!-- Gazebo ROS2 Control Plugin -->
  <gazebo>
    <plugin filename="libgazebo_ros2_control.so" name="gazebo_ros2_control">
      <robot_param>robot_description</robot_param>
      <robot_param_node>robot_state_publisher</robot_param_node>
      <parameters>$(arg controller_config_file)</parameters>
    </plugin>
  </gazebo>

</robot>